<?xml version="1.0" encoding="utf-8"?>
<robot
  name="TRLC-DK1-Follower">
  <link
    name="base_link">
    <inertial>
      <origin
        xyz="0 0 0"
        rpy="0 0 0" />
      <mass
        value="0.21" />
    </inertial>
    <visual>
      <origin
        xyz="0 0 0"
        rpy="0 0 0" />
      <geometry>
        <mesh
          filename="meshes/visual/base_link.dae" />
      </geometry>
      <material
        name="">
        <color
          rgba="0.95 0.95 0.95 1" />
      </material>
    </visual>
    <collision>
      <origin
        xyz="0 0 0"
        rpy="0 0 0" />
      <geometry>
        <mesh
          filename="meshes/collision/base_link.stl" />
      </geometry>
    </collision>
  </link>
  <link
    name="link1-2">
    <inertial>
      <origin
        xyz="0 0 0"
        rpy="0 0 0" />
      <mass
        value="0.09" />
    </inertial>
    <visual>
      <origin
        xyz="0 0 0"
        rpy="0 0 0" />
      <geometry>
        <mesh
          filename="meshes/visual/link1-2.dae" />
      </geometry>
      <material
        name="">
        <color
          rgba="0.95 0.95 0.95 1" />
      </material>
    </visual>
    <collision>
      <origin
        xyz="0 0 0"
        rpy="0 0 0" />
      <geometry>
        <mesh
          filename="meshes/collision/link1-2.stl" />
      </geometry>
    </collision>
  </link>
  <joint
    name="joint1"
    type="revolute">
    <origin
      xyz="0 0 0.0615"
      rpy="0 0 0" />
    <parent
      link="base_link" />
    <child
      link="link1-2" />
    <axis
      xyz="0 0 1" />
    <limit
      lower="-2.0943951023931953"
      upper="2.0943951023931953"
      effort="100"
      velocity="3" />
  </joint>
  <link
    name="link1">
    <inertial>
      <origin
        xyz="0 0 0"
        rpy="0 0 0" />
      <mass
        value="0.55" />
    </inertial>
    <visual>
      <origin
        xyz="0 0 0"
        rpy="0 0 0" />
      <geometry>
        <mesh
          filename="meshes/visual/link1.dae" />
      </geometry>
      <material
        name="">
        <color
          rgba="0.75 0.75 0.75 1" />
      </material>
    </visual>
    <collision>
      <origin
        xyz="0 0 0"
        rpy="0 0 0" />n <geometry>
        <mesh
          filename="meshes/collision/link1.stl" />
      </geometry>
    </collision>
  </link>
  <joint
    name="joint2"
    type="revolute">
    <origin
      xyz="0 0.02 0.0385"
      rpy="0 0 0" />
    <parent
      link="link1-2" />
    <child
      link="link1" />
    <axis
      xyz="1 0 0" />
    <limit
      lower="-3.141592653589793"
      upper="0"
      effort="100"
      velocity="3" />
  </joint>
  <link
    name="link2">
    <inertial>
      <origin
        xyz="0 0 0"
        rpy="0 0 0" />
      <mass
        value="0.54467" />
    </inertial>
    <visual>
      <origin
        xyz="0 0 0"
        rpy="0 0 0" />
      <geometry>
        <mesh
          filename="meshes/visual/link2.dae" />
      </geometry>
      <material
        name="">
        <color
          rgba="0.75 0.75 0.75 1" />
      </material>
    </visual>
    <collision>
      <origin
        xyz="0 0 0"
        rpy="0 0 0" />
      <geometry>
        <mesh
          filename="meshes/collision/link2.stl" />
      </geometry>
    </collision>
  </link>
  <joint
    name="joint3"
    type="revolute">
    <origin
      xyz="0 -0.264 0"
      rpy="0 0 0" />
    <parent
      link="link1" />
    <child
      link="link2" />
    <axis
      xyz="1 0 0" />
    <limit
      lower="0"
      upper="4.71238898038469"
      effort="100"
      velocity="3" />
  </joint>
  <link
    name="link4-5">
    <inertial>
      <origin
        xyz="0 0 0"
        rpy="0 0 0" />
      <mass
        value="0.361" />
    </inertial>
    <visual>
      <origin
        xyz="0 0 0"
        rpy="0 0 0" />
      <geometry>
        <mesh
          filename="meshes/visual/link4-5.dae" />
      </geometry>
      <material name="">
        <color
          rgba="0.95 0.95 0.95 1" />
      </material>
    </visual>
    <collision>
      <origin
        xyz="0 0 0"
        rpy="0 0 0" />
      <geometry>
        <mesh
          filename="meshes/collision/link4-5.stl" />
      </geometry>
    </collision>
  </link>
  <joint
    name="joint4"
    type="revolute">
    <origin
      xyz="0 0.244004 0.059971"
      rpy="0 0 0" />
    <parent
      link="link2" />
    <child
      link="link4-5" />
    <axis
      xyz="1 0 0" />
    <limit
      lower="-1.5707963267948966"
      upper="1.5707963267948966"
      effort="20"
      velocity="3" />
  </joint>
  <link
    name="link5-6">
    <inertial>
      <origin
        xyz="0 0 0"
        rpy="0 0 0" />
      <mass
        value="0.35879" />
    </inertial>
    <visual>
      <origin
        xyz="0 0 0"
        rpy="0 0 0" />
      <geometry>
        <mesh
          filename="meshes/visual/link5-6.dae" />
      </geometry>
      <material name="">
        <color
          rgba="0.95 0.95 0.95 1" />
      </material>
    </visual>
    <collision>
      <origin
        xyz="0 0 0"
        rpy="0 0 0" />
      <geometry>
        <mesh
          filename="meshes/collision/link5-6.stl" />
      </geometry>
    </collision>
  </link>
  <joint
    name="joint5"
    type="revolute">
    <origin
      xyz="0 0.061868 0.0425"
      rpy="0 0 0" />
    <parent
      link="link4-5" />
    <child
      link="link5-6" />
    <axis
      xyz="0 0 -1" />
    <limit
      lower="-1.5707963267948966"
      upper="1.5707963267948966"
      effort="20"
      velocity="3" />
  </joint>
  <link
    name="link6-7">
    <inertial>
      <origin
        xyz="0 0 0"
        rpy="0 0 0" />
      <mass
        value="0.45775" />
    </inertial>
    <visual>
      <origin
        xyz="0 0 0"
        rpy="0 0 0" />
      <geometry>
        <mesh
          filename="meshes/visual/link6-7.dae" />
      </geometry>
      <material name="">
        <color
          rgba="0.25 0.25 0.25 1" />
      </material>
    </visual>
    <collision>
      <origin
        xyz="0 0 0"
        rpy="0 0 0" />
      <geometry>
        <mesh
          filename="meshes/collision/link6-7.stl" />
      </geometry>
    </collision>
  </link>
  <joint
    name="joint6"
    type="revolute">
    <origin
      xyz="0.0 0.032 -0.0425"
      rpy="0 0 0" />
    <parent
      link="link5-6" />
    <child
      link="link6-7" />
    <axis
      xyz="0 1 0" />
    <limit
      lower="-3.141592653589793"
      upper="3.141592653589793"
      effort="20"
      velocity="3" />
  </joint>
  <link
    name="finger_left">
    <inertial>
      <origin
        xyz="0 0 0"
        rpy="0 0 0" />
      <mass
        value="0.037299" />
    </inertial>
    <visual>
      <origin
        xyz="0 0 0"
        rpy="0 0 0" />
      <geometry>
        <mesh
          filename="meshes/visual/finger_left.dae" />
      </geometry>
      <material name="">
        <color
          rgba="0.25 0.25 0.25 1" />
      </material>
    </visual>
    <collision>
      <origin
        xyz="0 0 0"
        rpy="0 0 0" />
      <geometry>
        <mesh
          filename="meshes/collision/finger_left.stl" />
      </geometry>
    </collision>
  </link>
  <joint
    name="gripper_left"
    type="prismatic">
    <origin
      xyz="0 0 0"
      rpy="0 0 0" />
    <parent
      link="link6-7" />
    <child
      link="finger_left" />
    <axis xyz="-1 0 0" />
    <limit
      lower="-0.045"
      upper="0.0"
      effort="20"
      velocity="0.2" />
  </joint>
  <link
    name="finger_right">
    <inertial>
      <origin
        xyz="0 0 0"
        rpy="0 0 0" />
      <mass
        value="0.037299" />
    </inertial>
    <visual>
      <origin
        xyz="0 0 0"
        rpy="0 0 0" />
      <geometry>
        <mesh
          filename="meshes/visual/finger_right.dae" />
      </geometry>
      <material name="">
        <color
          rgba="0.25 0.25 0.25 1" />
      </material>
    </visual>
    <collision>
      <origin
        xyz="0 0 0"
        rpy="0 0 0" />
      <geometry>
        <mesh
          filename="meshes/collision/finger_right.stl" />
      </geometry>
    </collision>
  </link>
  <joint
    name="gripper_right"
    type="prismatic">
    <origin
      xyz="0 0 0"
      rpy="0 0 0" />
    <parent
      link="link6-7" />
    <child
      link="finger_right" />
    <axis
      xyz="1 0 0" />
    <limit
      lower="-0.045"
      upper="0.0"
      effort="20"
      velocity="0.2" />
    <mimic joint="gripper_left" multiplier="1" offset="0" />
  </joint>
  <link name="tool0" />
  <joint name="gripper_tool0" type="fixed">
    <origin
      xyz="0 0.158 0"
      rpy="-1.5707963267948966 0 0" />
    <parent
      link="link6-7" />
    <child
      link="tool0" />
  </joint>
</robot>