<?xml version="1.0" encoding="utf-8"?>
<!-- This URDF was automatically created by SolidWorks to URDF Exporter! Originally created by Stephen Brawner (brawner@gmail.com) 
     Commit Version: 1.6.0-4-g7f85cfe  Build Version: 1.6.7995.38578
     For more information, please see http://wiki.ros.org/sw_urdf_exporter -->
<robot
  name="TRLC-DK1-Follower_URDF_v2">
  <link
    name="base_link">
    <inertial>
      <origin
        xyz="0 0 0"
        rpy="0 0 0" />
      <mass
        value="0.02782" />
      <inertia
        ixx="2.099E-05"
        ixy="-7.8904E-11"
        ixz="-2.3002E-11"
        iyy="4.6405E-05"
        iyz="5.0926E-11"
        izz="4.1402E-05" />
    </inertial>
    <visual>
      <origin
        xyz="0 0 0"
        rpy="0 0 0" />
      <geometry>
        <mesh
          filename="package://TRLC-DK1-Follower_URDF_v2/meshes/base_link.stl" />
      </geometry>
      <material
        name="">
        <color
          rgba="0.96078 0.96078 0.96471 1" />
      </material>
    </visual>
    <collision>
      <origin
        xyz="0 0 0"
        rpy="0 0 0" />
      <geometry>
        <mesh
          filename="package://TRLC-DK1-Follower_URDF_v2/meshes/base_link.stl" />
      </geometry>
    </collision>
  </link>
  <link
    name="link1-2">
    <inertial>
      <origin
        xyz="0 0 0"
        rpy="0 0 0" />
      <mass
        value="0.024532" />
      <inertia
        ixx="1.3789E-05"
        ixy="7.836E-06"
        ixz="-1.077E-06"
        iyy="2.9228E-05"
        iyz="-2.5729E-06"
        izz="3.0444E-05" />
    </inertial>
    <visual>
      <origin
        xyz="0 0 0"
        rpy="0 0 0" />
      <geometry>
        <mesh
          filename="package://TRLC-DK1-Follower_URDF_v2/meshes/link1-2.stl" />
      </geometry>
      <material
        name="">
        <color
          rgba="0.96078 0.96078 0.96471 1" />
      </material>
    </visual>
    <collision>
      <origin
        xyz="0 0 0"
        rpy="0 0 0" />
      <geometry>
        <mesh
          filename="package://TRLC-DK1-Follower_URDF_v2/meshes/link1-2.stl" />
      </geometry>
    </collision>
  </link>
  <joint
    name="Base_Joint"
    type="revolute">
    <origin
      xyz="0 0 0.06"
      rpy="0 0 0" />
    <parent
      link="base_link" />
    <child
      link="link1-2" />
    <axis
      xyz="0 0 1" />
    <limit
      lower="-6.28"
      upper="6.28"
      effort="0"
      velocity="0" />
  </joint>
  <link
    name="Link1">
    <inertial>
      <origin
        xyz="0 0 0"
        rpy="0 0 0" />
      <mass
        value="0.537601776973517" />
      <inertia
        ixx="0.00157171167790895"
        ixy="-0.00046460753958274"
        ixz="0.000219479025227951"
        iyy="0.000656277889913025"
        iyz="0.000524236672627174"
        izz="0.00145557081167622" />
    </inertial>
    <visual>
      <origin
        xyz="0 0 0"
        rpy="0 0 0" />
      <geometry>
        <mesh
          filename="package://TRLC-DK1-Follower_URDF_v2/meshes/Link1.stl" />
      </geometry>
      <material
        name="">
        <color
          rgba="0.752941176470588 0.752941176470588 0.752941176470588 1" />
      </material>
    </visual>
    <collision>
      <origin
        xyz="0 0 0"
        rpy="0 0 0" />
      <geometry>
        <mesh
          filename="package://TRLC-DK1-Follower_URDF_v2/meshes/Link1.stl" />
      </geometry>
    </collision>
  </link>
  <joint
    name="Joint_2"
    type="revolute">
    <origin
      xyz="0 0.02 0.0385"
      rpy="0 0 0" />
    <parent
      link="link1-2" />
    <child
      link="Link1" />
    <axis
      xyz="1 0 0" />
    <limit
      lower="-3.4"
      upper="0.27"
      effort="0"
      velocity="0" />
  </joint>
  <link
    name="Link_2">
    <inertial>
      <origin
        xyz="0 0 0"
        rpy="0 0 0" />
      <mass
        value="0.299922094541001" />
      <inertia
        ixx="0.000540301993803001"
        ixy="-0.000187970239396418"
        ixz="1.31724170144096E-05"
        iyy="0.000170079721765692"
        iyz="3.13483359447147E-05"
        izz="0.000578820329406052" />
    </inertial>
    <visual>
      <origin
        xyz="0 0 0"
        rpy="0 0 0" />
      <geometry>
        <mesh
          filename="package://TRLC-DK1-Follower_URDF_v2/meshes/Link_2.stl" />
      </geometry>
      <material
        name="">
        <color
          rgba="0.752941176470588 0.752941176470588 0.752941176470588 1" />
      </material>
    </visual>
    <collision>
      <origin
        xyz="0 0 0"
        rpy="0 0 0" />
      <geometry>
        <mesh
          filename="package://TRLC-DK1-Follower_URDF_v2/meshes/Link_2.stl" />
      </geometry>
    </collision>
  </link>
  <joint
    name="Joint_3"
    type="revolute">
    <origin
      xyz="0 -0.264 0"
      rpy="0 0 0" />
    <parent
      link="Link1" />
    <child
      link="Link_2" />
    <axis
      xyz="1 0 0" />
    <limit
      lower="0"
      upper="4.95"
      effort="0"
      velocity="0" />
  </joint>
  <link
    name="link4-5">
    <inertial>
      <origin
        xyz="0 0 0"
        rpy="0 0 0" />
      <mass
        value="0.0142938416889126" />
      <inertia
        ixx="1.19004851586458E-05"
        ixy="3.34981146101962E-06"
        ixz="-1.56617016842922E-06"
        iyy="1.85004964973935E-05"
        iyz="-3.74137891126362E-06"
        izz="1.78854619245037E-05" />
    </inertial>
    <visual>
      <origin
        xyz="0 0 0"
        rpy="0 0 0" />
      <geometry>
        <mesh
          filename="package://TRLC-DK1-Follower_URDF_v2/meshes/link4-5.stl" />
      </geometry>
      <material
        name="">
        <color
          rgba="0.96078431372549 0.96078431372549 0.964705882352941 1" />
      </material>
    </visual>
    <collision>
      <origin
        xyz="0 0 0"
        rpy="0 0 0" />
      <geometry>
        <mesh
          filename="package://TRLC-DK1-Follower_URDF_v2/meshes/link4-5.stl" />
      </geometry>
    </collision>
  </link>
  <joint
    name="Joint_4"
    type="revolute">
    <origin
      xyz="0 0.244004 0.059971"
      rpy="0 0 0" />
    <parent
      link="Link_2" />
    <child
      link="link4-5" />
    <axis
      xyz="-1 0 0" />
    <limit
      lower="-1.6"
      upper="2.2"
      effort="0"
      velocity="0" />
  </joint>
  <link
    name="link5-6">
    <inertial>
      <origin
        xyz="0 0 0"
        rpy="0 0 0" />
      <mass
        value="0.11909711022403" />
      <inertia
        ixx="3.93613431216204E-05"
        ixy="5.4049772026762E-06"
        ixz="7.63000534350956E-07"
        iyy="4.60524619539394E-05"
        iyz="1.44923342895047E-06"
        izz="3.3356206506896E-05" />
    </inertial>
    <visual>
      <origin
        xyz="0 0 0"
        rpy="0 0 0" />
      <geometry>
        <mesh
          filename="package://TRLC-DK1-Follower_URDF_v2/meshes/link5-6.stl" />
      </geometry>
      <material
        name="">
        <color
          rgba="0.96078431372549 0.96078431372549 0.964705882352941 1" />
      </material>
    </visual>
    <collision>
      <origin
        xyz="0 0 0"
        rpy="0 0 0" />
      <geometry>
        <mesh
          filename="package://TRLC-DK1-Follower_URDF_v2/meshes/link5-6.stl" />
      </geometry>
    </collision>
  </link>
  <joint
    name="Joint_5"
    type="revolute">
    <origin
      xyz="0 0.061993 0.038"
      rpy="0 0 0" />
    <parent
      link="link4-5" />
    <child
      link="link5-6" />
    <axis
      xyz="0 0 1" />
    <limit
      lower="-1.57"
      upper="1.57"
      effort="0"
      velocity="0" />
  </joint>
  <link
    name="Link6-7">
    <inertial>
      <origin
        xyz="0 0 0"
        rpy="0 0 0" />
      <mass
        value="0.289722572316062" />
      <inertia
        ixx="0.000117446622646519"
        ixy="4.81173421730959E-05"
        ixz="-1.34417340618578E-05"
        iyy="0.000168014216574977"
        iyz="1.18839604483301E-05"
        izz="0.000169419353992404" />
    </inertial>
    <visual>
      <origin
        xyz="0 0 0"
        rpy="0 0 0" />
      <geometry>
        <mesh
          filename="package://TRLC-DK1-Follower_URDF_v2/meshes/Link6-7.stl" />
      </geometry>
      <material
        name="">
        <color
          rgba="0.247058823529412 0.247058823529412 0.247058823529412 1" />
      </material>
    </visual>
    <collision>
      <origin
        xyz="0 0 0"
        rpy="0 0 0" />
      <geometry>
        <mesh
          filename="package://TRLC-DK1-Follower_URDF_v2/meshes/Link6-7.stl" />
      </geometry>
    </collision>
  </link>
  <joint
    name="Gripper_Rot"
    type="revolute">
    <origin
      xyz="0.0 0.032 -0.0375"
      rpy="0 0 0" />
    <parent
      link="link5-6" />
    <child
      link="Link6-7" />
    <axis
      xyz="0 -1 0" />
    <limit
      lower="-3.14"
      upper="3.14"
      effort="0"
      velocity="0" />
  </joint>
  <link
    name="finger_left">
    <inertial>
      <origin
        xyz="0 0 0"
        rpy="0 0 0" />
      <mass
        value="0.0745959905268717" />
      <inertia
        ixx="2.55177116500135E-05"
        ixy="-4.36022105863221E-06"
        ixz="1.08091124922434E-06"
        iyy="2.05389284814265E-05"
        iyz="-1.4290149214861E-06"
        izz="2.05479736979508E-05" />
    </inertial>
    <visual>
      <origin
        xyz="0 0 0"
        rpy="0 0 0" />
      <geometry>
        <mesh
          filename="package://TRLC-DK1-Follower_URDF_v2/meshes/finger_left.stl" />
      </geometry>
      <material
        name="">
        <color
          rgba="0.247058823529412 0.247058823529412 0.247058823529412 1" />
      </material>
    </visual>
    <collision>
      <origin
        xyz="0 0 0"
        rpy="0 0 0" />
      <geometry>
        <mesh
          filename="package://TRLC-DK1-Follower_URDF_v2/meshes/finger_left.stl" />
      </geometry>
    </collision>
  </link>
  <joint
    name="gripper_left"
    type="prismatic">
    <origin
      xyz="0 0 0"
      rpy="0 0 0" />
    <parent
      link="Link6-7" />
    <child
      link="finger_left" />
    <axis
      xyz="-1 0 0" />
    <limit
      lower="0.0"
      upper="0.04"
      effort="0"
      velocity="0" />
  </joint>
  <link
    name="finger_right">
    <inertial>
      <origin
        xyz="0 0 0"
        rpy="0 0 0" />
      <mass
        value="0.0745959905268717" />
      <inertia
        ixx="2.55177116500135E-05"
        ixy="-4.36022105863221E-06"
        ixz="1.08091124922434E-06"
        iyy="2.05389284814265E-05"
        iyz="-1.4290149214861E-06"
        izz="2.05479736979508E-05" />
    </inertial>
    <visual>
      <origin
        xyz="0 0 0"
        rpy="0 0 0" />
      <geometry>
        <mesh
          filename="package://TRLC-DK1-Follower_URDF_v2/meshes/finger_right.stl" />
      </geometry>
      <material
        name="">
        <color
          rgba="0.247058823529412 0.247058823529412 0.247058823529412 1" />
      </material>
    </visual>
    <collision>
      <origin
        xyz="0 0 0"
        rpy="0 0 0" />
      <geometry>
        <mesh
          filename="package://TRLC-DK1-Follower_URDF_v2/meshes/finger_right.stl" />
      </geometry>
    </collision>
  </link>
  <joint
    name="gripper_right"
    type="prismatic">
    <origin
      xyz="0 0 0"
      rpy="0 0 0" />
    <parent
      link="Link6-7" />
    <child
      link="finger_right" />
    <axis
      xyz="1 0 0" />
    <limit
      lower="0.0"
      upper="0.04"
      effort="0"
      velocity="0" />
    <mimic joint="gripper_left" multiplier="1" offset="0" />
  </joint>
</robot>
